Workbook

Sheet калькулятор
A1: Проект | B1: Тестовый проект | E1: Переход из предыдущего этапа (да/нет) | F1: Нет | K1: Должность | O1: РУПК | P1: Должность
E2: Старт нового этапа | O2: Условная должность
E3: Отношение к БС (для использования К переданных к перевыставлению затрат) | F3: Нет | G3: 1 | K3: ФИО | O3: Тестова Восемнадцать | P3: ФИО
K4: =IF(OR(O1="КУПК (РП/ЗРП)",O1="КУПК"),"NPV стартовый","") | P4: =IF(OR(T1="КУПК (РП/ЗРП)",T1="КУПК"),"NPV стартовый","")
K5: Дата начала работы на этапе | O5: 45748 | P5: Дата начала работы на этапе
K6: Длительность текущего этапа | O6: =(MAX($G15:$G39,K15:K39))-O$5+1 -> 548 | P6: Длительность текущего этапа | T6: =(MAX($G15:$G39,P15:P39))-T$5+1 -> 46296
K7: Проектный бонус (ПБ) этапа с учетом % загруженности | O7: =IFERROR(SUM(O$45:O$79),0) -> 3603287.7 | P7: Проектный бонус (ПБ) этапа с учетом % загруженности | T7: =IFERROR(SUM(T$45:T$79),0) -> 0
K8: Сумма на авансы по вехам | O8: =O$7*0.67 -> 2414202.7 | P8: Сумма на авансы по вехам | T8: =T$7*0.67 -> 0
K9: Остаток бонуса на финал этапа (при 100% выполнении сроков) | O9: =O$7-O$8 -> 1189084.9 | P9: Остаток бонуса на финал этапа (при 100% выполнении сроков) | T9: =T$7-T$8 -> 0
K10: =IF(OR(O1="КУПК (РП/ЗРП)",O1="КУПК"),"Коэф.фин.результата этапа","") | O10: =IF(O1="КУПК (РП/ЗРП)",MIN(1.5,MAX(0.5,IF(O4<500000000,IF(ABS(O11-O4)>50000000,1+0.05/100000000*(O11-O4),1),O11/O4))),IF(O1="КУПК",MIN(1.25,MAX(0.75,IF(O4<500000000, IF(ABS(O11-O4)>50000000,1+0.05/100000000*(O11-O4),1),O11/O4))),"")) | P10: =IF(OR(T1="КУПК (РП/ЗРП)",T1="КУПК"),"Коэф.фин.результата этапа","") | T10: =IF(T1="КУПК (РП/ЗРП)",MIN(1.5,MAX(0.5,IF(T4<500000000,IF(ABS(T11-T4)>50000000,1+0.05/100000000*(T11-T4),1),T11/T4))),IF(T1="КУПК",MIN(1.25,MAX(0.75,IF(T4<500000000, IF(ABS(T11-T4)>50000000,1+0.05/100000000*(T11-T4),1),T11/T4))),""))
K11: =IF(OR(O1="КУПК (РП/ЗРП)",O1="КУПК"),"NPV текущий","") | P11: =IF(OR(T1="КУПК (РП/ЗРП)",T1="КУПК"),"NPV текущий","")
K13: =IF(O12="","","Остаток бонуса на конец этапа") | O13: {=IFERROR(IF(O$12="","",IF($H36="","",IF(K36="",_xlfn.IFS(O$1="МП", IF(((O$7*IF(AND(OR(O$1="КУПК",O$1="РУПК"),$F$3="Да"),90%+10%*MAX(0,MIN(1,($G$3-40%)*2)),1))/O$6*(O$12-O$5+IF(K$12="Дата ухода с проекта (этапа)",1,0)))*(1+(MIN(0,$I36)*1%))*((AVERAGE(O16:O35)-50%)*2)-SUM(N16:N35)<0, 0, ((O$7*IF(AND(OR(O$1="КУПК",O$1="РУПК"),$F$3="Да"),90%+10%*MAX(0,MIN(1,($G$3-40%)*2)),1))/O$6*(O$12-O$5+IF(K$12="Дата ухода с проекта (этапа)",1,0)))*(1+(MIN(0,$I36)*1%))*((AVERAGE(O16:O35)-50%)*2)-SUM(N16:N35)),O$1="РУПК", IF(((O$7*IF(AND(OR(O$1="КУПК",O$1="РУПК"),$F$3="Да"),90%+10%*MAX(0,MIN(1,($G$3-40%)*2)),1))/O$6*(O$12-O$5+IF(K$12="Дата ухода с проекта (этапа)",1,0)))*(1+(MIN(0,$I36)*1%))-SUM(N16:N35)<0, 0, ((O$7*IF(AND(OR(O$1="КУПК",O$1="РУПК"),$F$3="Да"),90%+10%*MAX(0,MIN(1,($G$3-40%)*2)),1))/O$6*(O$12-O$5+IF(K$12="Дата ухода с проекта (этапа)",1,0)))*(1+(MIN(0,$I36)*1%))-SUM(N16:N35)),OR(O$1="КУПК",O$1="КУПК (РП/ЗРП)"), IF(((O$7*IF(AND(OR(O$1="КУПК",O$1="РУПК"),$F$3="Да"),90%+10%*MAX(0,MIN(1,($G$3-40%)*2)),1))/O$6*(O$12-O$5+IF(K$12="Дата ухода с проекта (этапа)",1,0)))*O$10*(1+(MIN(0,$I36)*1%))-SUM(N16:N35)<0, 0, ((O$7*IF(AND(OR(O$1="КУПК",O$1="РУПК"),$F$3="Да"),90%+10%*MAX(0,MIN(1,($G$3-40%)*2)),1))/O$6*(O$12-O$5+IF(K$12="Дата ухода с проекта (этапа)",1,0)))*O$10*(1+(MIN(0,$I36)*1%))-SUM(N16:N35))),_xlfn.IFS(O$1="МП", IF(((O$7*IF(AND(OR(O$1="КУПК",O$1="РУПК"),$F$3="Да"),90%+10%*MAX(0,MIN(1,($G$3-40%)*2)),1))/O$6*(O$12-O$5+IF(K$12="Дата ухода с проекта (этапа)",1,0)))*(1+(MIN(0,K36-$H36)*1%))*((AVERAGE(O16:O35)-50%)*2)-SUM(N16:N35)<0, 0, ((O$7*IF(AND(OR(O$1="КУПК",O$1="РУПК"),$F$3="Да"),90%+10%*MAX(0,MIN(1,($G$3-40%)*2)),1))/O$6*(O$12-O$5+IF(K$12="Дата ухода с проекта (этапа)",1,0)))*(1+(MIN(0,K36-$H36)*1%))*((AVERAGE(O16:O35)-50%)*2)-SUM(N16:N35)),O$1="РУПК", IF(((O$7*IF(AND(OR(O$1="КУПК",O$1="РУПК"),$F$3="Да"),90%+10%*MAX(0,MIN(1,($G$3-40%)*2)),1))/O$6*(O$12-O$5+IF(K$12="Дата ухода с проекта (этапа)",1,0)))*(1+(MIN(0,K36-$H36)*1%))-SUM(N16:N35)<0, 0, ((O$7*IF(AND(OR(O$1="КУПК",O$1="РУПК"),$F$3="Да"),90%+10%*MAX(0,MIN(1,($G$3-40%)*2)),1))/O$6*(O$12-O$5+IF(K$12="Дата ухода с проекта (этапа)",1,0)))*(1+(MIN(0,K36-$H36)*1%))-SUM(N16:N35)),OR(O$1="КУПК",O$1="КУПК (РП/ЗРП)"), IF(((O$7*IF(AND(OR(O$1="КУПК",O$1="РУПК"),$F$3="Да"),90%+10%*MAX(0,MIN(1,($G$3-40%)*2)),1))/O$6*(O$12-O$5+IF(K$12="Дата ухода с проекта (этапа)",1,0)))*O$10*(1+(MIN(0,K36-$H36)*1%))-SUM(N16:N35)<0, 0, ((O$7*IF(AND(OR(O$1="КУПК",O$1="РУПК"),$F$3="Да"),90%+10%*MAX(0,MIN(1,($G$3-40%)*2)),1))/O$6*(O$12-O$5+IF(K$12="Дата ухода с проекта (этапа)",1,0)))*O$10*(1+(MIN(0,K36-$H36)*1%))-SUM(N16:N35)))))),"")} | P13: =IF(T12="","","Остаток бонуса на конец этапа") | T13: {=IFERROR(IF(T$12="","",IF($H36="","",IF(P36="",_xlfn.IFS(T$1="МП", IF(((T$7*IF(AND(OR(T$1="КУПК",T$1="РУПК"),$F$3="Да"),90%+10%*MAX(0,MIN(1,($G$3-40%)*2)),1))/T$6*(T$12-T$5+IF(P$12="Дата ухода с проекта (этапа)",1,0)))*(1+(MIN(0,$I36)*1%))*((AVERAGE(T16:T35)-50%)*2)-SUM(S16:S35)<0, 0, ((T$7*IF(AND(OR(T$1="КУПК",T$1="РУПК"),$F$3="Да"),90%+10%*MAX(0,MIN(1,($G$3-40%)*2)),1))/T$6*(T$12-T$5+IF(P$12="Дата ухода с проекта (этапа)",1,0)))*(1+(MIN(0,$I36)*1%))*((AVERAGE(T16:T35)-50%)*2)-SUM(S16:S35)),T$1="РУПК", IF(((T$7*IF(AND(OR(T$1="КУПК",T$1="РУПК"),$F$3="Да"),90%+10%*MAX(0,MIN(1,($G$3-40%)*2)),1))/T$6*(T$12-T$5+IF(P$12="Дата ухода с проекта (этапа)",1,0)))*(1+(MIN(0,$I36)*1%))-SUM(S16:S35)<0, 0, ((T$7*IF(AND(OR(T$1="КУПК",T$1="РУПК"),$F$3="Да"),90%+10%*MAX(0,MIN(1,($G$3-40%)*2)),1))/T$6*(T$12-T$5+IF(P$12="Дата ухода с проекта (этапа)",1,0)))*(1+(MIN(0,$I36)*1%))-SUM(S16:S35)),OR(T$1="КУПК",T$1="КУПК (РП/ЗРП)"), IF(((T$7*IF(AND(OR(T$1="КУПК",T$1="РУПК"),$F$3="Да"),90%+10%*MAX(0,MIN(1,($G$3-40%)*2)),1))/T$6*(T$12-T$5+IF(P$12="Дата ухода с проекта (этапа)",1,0)))*T$10*(1+(MIN(0,$I36)*1%))-SUM(S16:S35)<0, 0, ((T$7*IF(AND(OR(T$1="КУПК",T$1="РУПК"),$F$3="Да"),90%+10%*MAX(0,MIN(1,($G$3-40%)*2)),1))/T$6*(T$12-T$5+IF(P$12="Дата ухода с проекта (этапа)",1,0)))*T$10*(1+(MIN(0,$I36)*1%))-SUM(S16:S35))),_xlfn.IFS(T$1="МП", IF(((T$7*IF(AND(OR(T$1="КУПК",T$1="РУПК"),$F$3="Да"),90%+10%*MAX(0,MIN(1,($G$3-40%)*2)),1))/T$6*(T$12-T$5+IF(P$12="Дата ухода с проекта (этапа)",1,0)))*(1+(MIN(0,P36-$H36)*1%))*((AVERAGE(T16:T35)-50%)*2)-SUM(S16:S35)<0, 0, ((T$7*IF(AND(OR(T$1="КУПК",T$1="РУПК"),$F$3="Да"),90%+10%*MAX(0,MIN(1,($G$3-40%)*2)),1))/T$6*(T$12-T$5+IF(P$12="Дата ухода с проекта (этапа)",1,0)))*(1+(MIN(0,P36-$H36)*1%))*((AVERAGE(T16:T35)-50%)*2)-SUM(S16:S35)),T$1="РУПК", IF(((T$7*IF(AND(OR(T$1="КУПК",T$1="РУПК"),$F$3="Да"),90%+10%*MAX(0,MIN(1,($G$3-40%)*2)),1))/T$6*(T$12-T$5+IF(P$12="Дата ухода с проекта (этапа)",1,0)))*(1+(MIN(0,P36-$H36)*1%))-SUM(S16:S35)<0, 0, ((T$7*IF(AND(OR(T$1="КУПК",T$1="РУПК"),$F$3="Да"),90%+10%*MAX(0,MIN(1,($G$3-40%)*2)),1))/T$6*(T$12-T$5+IF(P$12="Дата ухода с проекта (этапа)",1,0)))*(1+(MIN(0,P36-$H36)*1%))-SUM(S16:S35)),OR(T$1="КУПК",T$1="КУПК (РП/ЗРП)"), IF(((T$7*IF(AND(OR(T$1="КУПК",T$1="РУПК"),$F$3="Да"),90%+10%*MAX(0,MIN(1,($G$3-40%)*2)),1))/T$6*(T$12-T$5+IF(P$12="Дата ухода с проекта (этапа)",1,0)))*T$10*(1+(MIN(0,P36-$H36)*1%))-SUM(S16:S35)<0, 0, ((T$7*IF(AND(OR(T$1="КУПК",T$1="РУПК"),$F$3="Да"),90%+10%*MAX(0,MIN(1,($G$3-40%)*2)),1))/T$6*(T$12-T$5+IF(P$12="Дата ухода с проекта (этапа)",1,0)))*T$10*(1+(MIN(0,P36-$H36)*1%))-SUM(S16:S35)))))),"")}
K14: Итого к выплате за отчётный квартал | P14: Итого к выплате за отчётный квартал
C15: Этап | D15: №п/п | E15: Наименование вехи | F15: Корпус/ Строение/ Очередь | G15: Плановый срок | H15: Фактический срок выполнения | I15: Просрочка/опережение к.дн | J15: Дата выплаты бонуса за веху | K15: Инд. Срок | M15: Вес вехи | N15: Сумма бонуса вехи | O15: =IF(OR(O1="КУПК (РП/ЗРП)",O1="КУПК"),"Комментарий/NPV/KPI","Комментарий") -> Комментарий | P15: Инд. Срок | R15: Вес вехи | S15: Сумма бонуса вехи | T15: =IF(OR(T1="КУПК (РП/ЗРП)",T1="КУПК"),"Комментарий/NPV/KPI","Комментарий") -> Комментарий
B16: =CONCATENATE(E16," ",F16) -> Мотивационная веха 1 | C16: 4 | D16: 1 | E16: Мотивационная веха 1 | G16: 45838 | H16: 45838 | I16: =IF(H16="","",G16-H16) -> 0 | J16: =IF(H16="","",(DATE(YEAR(H16),ROUNDUP(MONTH(H16)/3,0)*3+2,10)-IF(WEEKDAY(DATE(YEAR(H16),ROUNDUP(MONTH(H16)/3,0)*3+2,10),2)>5,WEEKDAY(DATE(YEAR(H16),ROUNDUP(MONTH(H16)/3,0)*3+2,10),2)-5,0))) -> 45877 | M16: {=IFERROR( IF($E16="","",IF(AND($F$1="Да",$F$2=O$5),IF(COUNTIF($E$16:$E$35,"<>")=0,"Веха не участвует в расчете выплат за квартал",1/COUNTIF($E$16:$E$35,"<>")),IF(IF(K16="",$G16,K16)="", "Веха не участвует в расчете выплат за квартал", IF(INT(IF(K16="",$G16,K16))<INT(O$5+60), "Веха не участвует в расчете выплат за квартал", IF(SUMPRODUCT(($E$16:$E$35<>"")*(IF(IF(K$16:K$35="",$G$16:$G$35,K$16:K$35)="",0,INT(IF(K$16:K$35="",$G$16:$G$35,K$16:K$35)))>=INT(O$5+60)))=0,"Веха не участвует в расчете выплат за квартал",1/SUMPRODUCT(($E$16:$E$35<>"")*(IF(IF(K$16:K$35="",$G$16:$G$35,K$16:K$35)="",0,INT(IF(K$16:K$35="",$G$16:$G$35,K$16:K$35)))>=INT(O$5+60)))))))),"")} -> 0.16666667 | N16: =IFERROR(IF(AND(O$12<>"",$H16>O$12),0,IF($I16<-100,0,IF(IF(AND($F$1="Да",$F$2=O$5),TRUE(),IF(K16="",$G16,K16)>=O$5+60),IF($H16="","",IF(AND(O$1="МП",_xlfn.ISFORMULA(O16)),"Впиши средний KPI за прошлые кварталы",O$8*M16*IF(AND(OR(O$1="КУПК",O$1="РУПК"),$F$3="Да"),90%+10%*MAX(0,MIN(1,($G$3-40%)*2)),1)*MIN((1+IF(K16="",$I16,K16-$H16)*1%)*IF(O$1="РУПК",1,IF(O$1="МП",(O16-50%)*2,O$10)),IF(O$1="РУПК",1.5,IF(O$1="МП",(O16-50%)*2*1.5,1.5*O$10))))),"Веха не участвует в расчете выплат за квартал"))),"") -> 402367.12 | O16: =IFERROR(IF(ISTEXT(N16),"",IF(AND(OR(O$1="КУПК",O$1="КУПК (РП/ЗРП)"),N16>0),IF($H16="","",CONCATENATE("Расчёт при NPV = ",TEXT(O$11,"# ##0 ₽"),". Коэф. фин. рез. = ",ROUND(O$10,2))),"")),"") | R16: {=IFERROR( IF($E16="","",IF(AND($F$1="Да",$F$2=T$5),IF(COUNTIF($E$16:$E$35,"<>")=0,"Веха не участвует в расчете выплат за квартал",1/COUNTIF($E$16:$E$35,"<>")),IF(IF(P16="",$G16,P16)="", "Веха не участвует в расчете выплат за квартал", IF(INT(IF(P16="",$G16,P16))<INT(T$5+60), "Веха не участвует в расчете выплат за квартал", IF(SUMPRODUCT(($E$16:$E$35<>"")*(IF(IF(P$16:P$35="",$G$16:$G$35,P$16:P$35)="",0,INT(IF(P$16:P$35="",$G$16:$G$35,P$16:P$35)))>=INT(T$5+60)))=0,"Веха не участвует в расчете выплат за квартал",1/SUMPRODUCT(($E$16:$E$35<>"")*(IF(IF(P$16:P$35="",$G$16:$G$35,P$16:P$35)="",0,INT(IF(P$16:P$35="",$G$16:$G$35,P$16:P$35)))>=INT(T$5+60)))))))),"")} -> 0.16666667 | S16: =IFERROR(IF(AND(T$12<>"",$H16>T$12),0,IF($I16<-100,0,IF(IF(AND($F$1="Да",$F$2=T$5),TRUE(),IF(P16="",$G16,P16)>=T$5+60),IF($H16="","",IF(AND(T$1="МП",_xlfn.ISFORMULA(T16)),"Впиши средний KPI за прошлые кварталы",T$8*R16*IF(AND(OR(T$1="КУПК",T$1="РУПК"),$F$3="Да"),90%+10%*MAX(0,MIN(1,($G$3-40%)*2)),1)*MIN((1+IF(P16="",$I16,P16-$H16)*1%)*IF(T$1="РУПК",1,IF(T$1="МП",(T16-50%)*2,T$10)),IF(T$1="РУПК",1.5,IF(T$1="МП",(T16-50%)*2*1.5,1.5*T$10))))),"Веха не участвует в расчете выплат за квартал"))),"") | T16: =IFERROR(IF(ISTEXT(S16),"",IF(AND(OR(T$1="КУПК",T$1="КУПК (РП/ЗРП)"),S16>0),IF($H16="","",CONCATENATE("Расчёт при NPV = ",TEXT(T$11,"# ##0 ₽"),". Коэф. фин. рез. = ",ROUND(T$10,2))),"")),"")
B17: =CONCATENATE(E17," ",F17) -> Мотивационная веха 2 | C17: 4 | D17: 2 | E17: Мотивационная веха 2 | G17: 45930 | I17: =IF(H17="","",G17-H17) | J17: =IF(H17="","",(DATE(YEAR(H17),ROUNDUP(MONTH(H17)/3,0)*3+2,10)-IF(WEEKDAY(DATE(YEAR(H17),ROUNDUP(MONTH(H17)/3,0)*3+2,10),2)>5,WEEKDAY(DATE(YEAR(H17),ROUNDUP(MONTH(H17)/3,0)*3+2,10),2)-5,0))) | M17: {=IFERROR( IF($E17="","",IF(AND($F$1="Да",$F$2=O$5),IF(COUNTIF($E$16:$E$35,"<>")=0,"Веха не участвует в расчете выплат за квартал",1/COUNTIF($E$16:$E$35,"<>")),IF(IF(K17="",$G17,K17)="", "Веха не участвует в расчете выплат за квартал", IF(INT(IF(K17="",$G17,K17))<INT(O$5+60), "Веха не участвует в расчете выплат за квартал", IF(SUMPRODUCT(($E$16:$E$35<>"")*(IF(IF(K$16:K$35="",$G$16:$G$35,K$16:K$35)="",0,INT(IF(K$16:K$35="",$G$16:$G$35,K$16:K$35)))>=INT(O$5+60)))=0,"Веха не участвует в расчете выплат за квартал",1/SUMPRODUCT(($E$16:$E$35<>"")*(IF(IF(K$16:K$35="",$G$16:$G$35,K$16:K$35)="",0,INT(IF(K$16:K$35="",$G$16:$G$35,K$16:K$35)))>=INT(O$5+60)))))))),"")} -> 0.16666667 | N17: =IFERROR(IF(AND(O$12<>"",$H17>O$12),0,IF($I17<-100,0,IF(IF(AND($F$1="Да",$F$2=O$5),TRUE(),IF(K17="",$G17,K17)>=O$5+60),IF($H17="","",IF(AND(O$1="МП",_xlfn.ISFORMULA(O17)),"Впиши средний KPI за прошлые кварталы",O$8*M17*IF(AND(OR(O$1="КУПК",O$1="РУПК"),$F$3="Да"),90%+10%*MAX(0,MIN(1,($G$3-40%)*2)),1)*MIN((1+IF(K17="",$I17,K17-$H17)*1%)*IF(O$1="РУПК",1,IF(O$1="МП",(O17-50%)*2,O$10)),IF(O$1="РУПК",1.5,IF(O$1="МП",(O17-50%)*2*1.5,1.5*O$10))))),"Веха не участвует в расчете выплат за квартал"))),"") | O17: =IFERROR(IF(ISTEXT(N17),"",IF(AND(OR(O$1="КУПК",O$1="КУПК (РП/ЗРП)"),N17>0),IF($H17="","",CONCATENATE("Расчёт при NPV = ",TEXT(O$11,"# ##0 ₽"),". Коэф. фин. рез. = ",ROUND(O$10,2))),"")),"") | R17: {=IFERROR( IF($E17="","",IF(AND($F$1="Да",$F$2=T$5),IF(COUNTIF($E$16:$E$35,"<>")=0,"Веха не участвует в расчете выплат за квартал",1/COUNTIF($E$16:$E$35,"<>")),IF(IF(P17="",$G17,P17)="", "Веха не участвует в расчете выплат за квартал", IF(INT(IF(P17="",$G17,P17))<INT(T$5+60), "Веха не участвует в расчете выплат за квартал", IF(SUMPRODUCT(($E$16:$E$35<>"")*(IF(IF(P$16:P$35="",$G$16:$G$35,P$16:P$35)="",0,INT(IF(P$16:P$35="",$G$16:$G$35,P$16:P$35)))>=INT(T$5+60)))=0,"Веха не участвует в расчете выплат за квартал",1/SUMPRODUCT(($E$16:$E$35<>"")*(IF(IF(P$16:P$35="",$G$16:$G$35,P$16:P$35)="",0,INT(IF(P$16:P$35="",$G$16:$G$35,P$16:P$35)))>=INT(T$5+60)))))))),"")} -> 0.16666667 | S17: =IFERROR(IF(AND(T$12<>"",$H17>T$12),0,IF($I17<-100,0,IF(IF(AND($F$1="Да",$F$2=T$5),TRUE(),IF(P17="",$G17,P17)>=T$5+60),IF($H17="","",IF(AND(T$1="МП",_xlfn.ISFORMULA(T17)),"Впиши средний KPI за прошлые кварталы",T$8*R17*IF(AND(OR(T$1="КУПК",T$1="РУПК"),$F$3="Да"),90%+10%*MAX(0,MIN(1,($G$3-40%)*2)),1)*MIN((1+IF(P17="",$I17,P17-$H17)*1%)*IF(T$1="РУПК",1,IF(T$1="МП",(T17-50%)*2,T$10)),IF(T$1="РУПК",1.5,IF(T$1="МП",(T17-50%)*2*1.5,1.5*T$10))))),"Веха не участвует в расчете выплат за квартал"))),"") | T17: =IFERROR(IF(ISTEXT(S17),"",IF(AND(OR(T$1="КУПК",T$1="КУПК (РП/ЗРП)"),S17>0),IF($H17="","",CONCATENATE("Расчёт при NPV = ",TEXT(T$11,"# ##0 ₽"),". Коэф. фин. рез. = ",ROUND(T$10,2))),"")),"")
B18: =CONCATENATE(E18," ",F18) -> Мотивационная веха 3 | C18: 4 | D18: =D17+1 -> 3 | E18: Мотивационная веха 3 | G18: 46006 | H18: 46006 | I18: =IF(H18="","",G18-H18) -> 0 | J18: =IF(H18="","",(DATE(YEAR(H18),ROUNDUP(MONTH(H18)/3,0)*3+2,10)-IF(WEEKDAY(DATE(YEAR(H18),ROUNDUP(MONTH(H18)/3,0)*3+2,10),2)>5,WEEKDAY(DATE(YEAR(H18),ROUNDUP(MONTH(H18)/3,0)*3+2,10),2)-5,0))) -> 46063 | M18: {=IFERROR( IF($E18="","",IF(AND($F$1="Да",$F$2=O$5),IF(COUNTIF($E$16:$E$35,"<>")=0,"Веха не участвует в расчете выплат за квартал",1/COUNTIF($E$16:$E$35,"<>")),IF(IF(K18="",$G18,K18)="", "Веха не участвует в расчете выплат за квартал", IF(INT(IF(K18="",$G18,K18))<INT(O$5+60), "Веха не участвует в расчете выплат за квартал", IF(SUMPRODUCT(($E$16:$E$35<>"")*(IF(IF(K$16:K$35="",$G$16:$G$35,K$16:K$35)="",0,INT(IF(K$16:K$35="",$G$16:$G$35,K$16:K$35)))>=INT(O$5+60)))=0,"Веха не участвует в расчете выплат за квартал",1/SUMPRODUCT(($E$16:$E$35<>"")*(IF(IF(K$16:K$35="",$G$16:$G$35,K$16:K$35)="",0,INT(IF(K$16:K$35="",$G$16:$G$35,K$16:K$35)))>=INT(O$5+60)))))))),"")} -> 0.16666667 | N18: =IFERROR(IF(AND(O$12<>"",$H18>O$12),0,IF($I18<-100,0,IF(IF(AND($F$1="Да",$F$2=O$5),TRUE(),IF(K18="",$G18,K18)>=O$5+60),IF($H18="","",IF(AND(O$1="МП",_xlfn.ISFORMULA(O18)),"Впиши средний KPI за прошлые кварталы",O$8*M18*IF(AND(OR(O$1="КУПК",O$1="РУПК"),$F$3="Да"),90%+10%*MAX(0,MIN(1,($G$3-40%)*2)),1)*MIN((1+IF(K18="",$I18,K18-$H18)*1%)*IF(O$1="РУПК",1,IF(O$1="МП",(O18-50%)*2,O$10)),IF(O$1="РУПК",1.5,IF(O$1="МП",(O18-50%)*2*1.5,1.5*O$10))))),"Веха не участвует в расчете выплат за квартал"))),"") -> 402367.12 | O18: =IFERROR(IF(ISTEXT(N18),"",IF(AND(OR(O$1="КУПК",O$1="КУПК (РП/ЗРП)"),N18>0),IF($H18="","",CONCATENATE("Расчёт при NPV = ",TEXT(O$11,"# ##0 ₽"),". Коэф. фин. рез. = ",ROUND(O$10,2))),"")),"") | R18: {=IFERROR( IF($E18="","",IF(AND($F$1="Да",$F$2=T$5),IF(COUNTIF($E$16:$E$35,"<>")=0,"Веха не участвует в расчете выплат за квартал",1/COUNTIF($E$16:$E$35,"<>")),IF(IF(P18="",$G18,P18)="", "Веха не участвует в расчете выплат за квартал", IF(INT(IF(P18="",$G18,P18))<INT(T$5+60), "Веха не участвует в расчете выплат за квартал", IF(SUMPRODUCT(($E$16:$E$35<>"")*(IF(IF(P$16:P$35="",$G$16:$G$35,P$16:P$35)="",0,INT(IF(P$16:P$35="",$G$16:$G$35,P$16:P$35)))>=INT(T$5+60)))=0,"Веха не участвует в расчете выплат за квартал",1/SUMPRODUCT(($E$16:$E$35<>"")*(IF(IF(P$16:P$35="",$G$16:$G$35,P$16:P$35)="",0,INT(IF(P$16:P$35="",$G$16:$G$35,P$16:P$35)))>=INT(T$5+60)))))))),"")} -> 0.16666667 | S18: =IFERROR(IF(AND(T$12<>"",$H18>T$12),0,IF($I18<-100,0,IF(IF(AND($F$1="Да",$F$2=T$5),TRUE(),IF(P18="",$G18,P18)>=T$5+60),IF($H18="","",IF(AND(T$1="МП",_xlfn.ISFORMULA(T18)),"Впиши средний KPI за прошлые кварталы",T$8*R18*IF(AND(OR(T$1="КУПК",T$1="РУПК"),$F$3="Да"),90%+10%*MAX(0,MIN(1,($G$3-40%)*2)),1)*MIN((1+IF(P18="",$I18,P18-$H18)*1%)*IF(T$1="РУПК",1,IF(T$1="МП",(T18-50%)*2,T$10)),IF(T$1="РУПК",1.5,IF(T$1="МП",(T18-50%)*2*1.5,1.5*T$10))))),"Веха не участвует в расчете выплат за квартал"))),"") | T18: =IFERROR(IF(ISTEXT(S18),"",IF(AND(OR(T$1="КУПК",T$1="КУПК (РП/ЗРП)"),S18>0),IF($H18="","",CONCATENATE("Расчёт при NPV = ",TEXT(T$11,"# ##0 ₽"),". Коэф. фин. рез. = ",ROUND(T$10,2))),"")),"")
B19: =CONCATENATE(E19," ",F19) -> Мотивационная веха 4 | C19: 4 | D19: =D18+1 -> 4 | E19: Мотивационная веха 4 | G19: 46112 | I19: =IF(H19="","",G19-H19) | J19: =IF(H19="","",(DATE(YEAR(H19),ROUNDUP(MONTH(H19)/3,0)*3+2,10)-IF(WEEKDAY(DATE(YEAR(H19),ROUNDUP(MONTH(H19)/3,0)*3+2,10),2)>5,WEEKDAY(DATE(YEAR(H19),ROUNDUP(MONTH(H19)/3,0)*3+2,10),2)-5,0))) | M19: {=IFERROR( IF($E19="","",IF(AND($F$1="Да",$F$2=O$5),IF(COUNTIF($E$16:$E$35,"<>")=0,"Веха не участвует в расчете выплат за квартал",1/COUNTIF($E$16:$E$35,"<>")),IF(IF(K19="",$G19,K19)="", "Веха не участвует в расчете выплат за квартал", IF(INT(IF(K19="",$G19,K19))<INT(O$5+60), "Веха не участвует в расчете выплат за квартал", IF(SUMPRODUCT(($E$16:$E$35<>"")*(IF(IF(K$16:K$35="",$G$16:$G$35,K$16:K$35)="",0,INT(IF(K$16:K$35="",$G$16:$G$35,K$16:K$35)))>=INT(O$5+60)))=0,"Веха не участвует в расчете выплат за квартал",1/SUMPRODUCT(($E$16:$E$35<>"")*(IF(IF(K$16:K$35="",$G$16:$G$35,K$16:K$35)="",0,INT(IF(K$16:K$35="",$G$16:$G$35,K$16:K$35)))>=INT(O$5+60)))))))),"")} -> 0.16666667 | N19: =IFERROR(IF(AND(O$12<>"",$H19>O$12),0,IF($I19<-100,0,IF(IF(AND($F$1="Да",$F$2=O$5),TRUE(),IF(K19="",$G19,K19)>=O$5+60),IF($H19="","",IF(AND(O$1="МП",_xlfn.ISFORMULA(O19)),"Впиши средний KPI за прошлые кварталы",O$8*M19*IF(AND(OR(O$1="КУПК",O$1="РУПК"),$F$3="Да"),90%+10%*MAX(0,MIN(1,($G$3-40%)*2)),1)*MIN((1+IF(K19="",$I19,K19-$H19)*1%)*IF(O$1="РУПК",1,IF(O$1="МП",(O19-50%)*2,O$10)),IF(O$1="РУПК",1.5,IF(O$1="МП",(O19-50%)*2*1.5,1.5*O$10))))),"Веха не участвует в расчете выплат за квартал"))),"") | O19: =IFERROR(IF(ISTEXT(N19),"",IF(AND(OR(O$1="КУПК",O$1="КУПК (РП/ЗРП)"),N19>0),IF($H19="","",CONCATENATE("Расчёт при NPV = ",TEXT(O$11,"# ##0 ₽"),". Коэф. фин. рез. = ",ROUND(O$10,2))),"")),"") | R19: {=IFERROR( IF($E19="","",IF(AND($F$1="Да",$F$2=T$5),IF(COUNTIF($E$16:$E$35,"<>")=0,"Веха не участвует в расчете выплат за квартал",1/COUNTIF($E$16:$E$35,"<>")),IF(IF(P19="",$G19,P19)="", "Веха не участвует в расчете выплат за квартал", IF(INT(IF(P19="",$G19,P19))<INT(T$5+60), "Веха не участвует в расчете выплат за квартал", IF(SUMPRODUCT(($E$16:$E$35<>"")*(IF(IF(P$16:P$35="",$G$16:$G$35,P$16:P$35)="",0,INT(IF(P$16:P$35="",$G$16:$G$35,P$16:P$35)))>=INT(T$5+60)))=0,"Веха не участвует в расчете выплат за квартал",1/SUMPRODUCT(($E$16:$E$35<>"")*(IF(IF(P$16:P$35="",$G$16:$G$35,P$16:P$35)="",0,INT(IF(P$16:P$35="",$G$16:$G$35,P$16:P$35)))>=INT(T$5+60)))))))),"")} -> 0.16666667 | S19: =IFERROR(IF(AND(T$12<>"",$H19>T$12),0,IF($I19<-100,0,IF(IF(AND($F$1="Да",$F$2=T$5),TRUE(),IF(P19="",$G19,P19)>=T$5+60),IF($H19="","",IF(AND(T$1="МП",_xlfn.ISFORMULA(T19)),"Впиши средний KPI за прошлые кварталы",T$8*R19*IF(AND(OR(T$1="КУПК",T$1="РУПК"),$F$3="Да"),90%+10%*MAX(0,MIN(1,($G$3-40%)*2)),1)*MIN((1+IF(P19="",$I19,P19-$H19)*1%)*IF(T$1="РУПК",1,IF(T$1="МП",(T19-50%)*2,T$10)),IF(T$1="РУПК",1.5,IF(T$1="МП",(T19-50%)*2*1.5,1.5*T$10))))),"Веха не участвует в расчете выплат за квартал"))),"") | T19: =IFERROR(IF(ISTEXT(S19),"",IF(AND(OR(T$1="КУПК",T$1="КУПК (РП/ЗРП)"),S19>0),IF($H19="","",CONCATENATE("Расчёт при NPV = ",TEXT(T$11,"# ##0 ₽"),". Коэф. фин. рез. = ",ROUND(T$10,2))),"")),"")
B20: =CONCATENATE(E20," ",F20) -> Мотивационная веха 5 | C20: 4 | D20: =D19+1 -> 5 | E20: Мотивационная веха 5 | G20: 46171 | I20: =IF(H20="","",G20-H20) | J20: =IF(H20="","",(DATE(YEAR(H20),ROUNDUP(MONTH(H20)/3,0)*3+2,10)-IF(WEEKDAY(DATE(YEAR(H20),ROUNDUP(MONTH(H20)/3,0)*3+2,10),2)>5,WEEKDAY(DATE(YEAR(H20),ROUNDUP(MONTH(H20)/3,0)*3+2,10),2)-5,0))) | M20: {=IFERROR( IF($E20="","",IF(AND($F$1="Да",$F$2=O$5),IF(COUNTIF($E$16:$E$35,"<>")=0,"Веха не участвует в расчете выплат за квартал",1/COUNTIF($E$16:$E$35,"<>")),IF(IF(K20="",$G20,K20)="", "Веха не участвует в расчете выплат за квартал", IF(INT(IF(K20="",$G20,K20))<INT(O$5+60), "Веха не участвует в расчете выплат за квартал", IF(SUMPRODUCT(($E$16:$E$35<>"")*(IF(IF(K$16:K$35="",$G$16:$G$35,K$16:K$35)="",0,INT(IF(K$16:K$35="",$G$16:$G$35,K$16:K$35)))>=INT(O$5+60)))=0,"Веха не участвует в расчете выплат за квартал",1/SUMPRODUCT(($E$16:$E$35<>"")*(IF(IF(K$16:K$35="",$G$16:$G$35,K$16:K$35)="",0,INT(IF(K$16:K$35="",$G$16:$G$35,K$16:K$35)))>=INT(O$5+60)))))))),"")} -> 0.16666667 | N20: =IFERROR(IF(AND(O$12<>"",$H20>O$12),0,IF($I20<-100,0,IF(IF(AND($F$1="Да",$F$2=O$5),TRUE(),IF(K20="",$G20,K20)>=O$5+60),IF($H20="","",IF(AND(O$1="МП",_xlfn.ISFORMULA(O20)),"Впиши средний KPI за прошлые кварталы",O$8*M20*IF(AND(OR(O$1="КУПК",O$1="РУПК"),$F$3="Да"),90%+10%*MAX(0,MIN(1,($G$3-40%)*2)),1)*MIN((1+IF(K20="",$I20,K20-$H20)*1%)*IF(O$1="РУПК",1,IF(O$1="МП",(O20-50%)*2,O$10)),IF(O$1="РУПК",1.5,IF(O$1="МП",(O20-50%)*2*1.5,1.5*O$10))))),"Веха не участвует в расчете выплат за квартал"))),"") | O20: =IFERROR(IF(ISTEXT(N20),"",IF(AND(OR(O$1="КУПК",O$1="КУПК (РП/ЗРП)"),N20>0),IF($H20="","",CONCATENATE("Расчёт при NPV = ",TEXT(O$11,"# ##0 ₽"),". Коэф. фин. рез. = ",ROUND(O$10,2))),"")),"") | R20: {=IFERROR( IF($E20="","",IF(AND($F$1="Да",$F$2=T$5),IF(COUNTIF($E$16:$E$35,"<>")=0,"Веха не участвует в расчете выплат за квартал",1/COUNTIF($E$16:$E$35,"<>")),IF(IF(P20="",$G20,P20)="", "Веха не участвует в расчете выплат за квартал", IF(INT(IF(P20="",$G20,P20))<INT(T$5+60), "Веха не участвует в расчете выплат за квартал", IF(SUMPRODUCT(($E$16:$E$35<>"")*(IF(IF(P$16:P$35="",$G$16:$G$35,P$16:P$35)="",0,INT(IF(P$16:P$35="",$G$16:$G$35,P$16:P$35)))>=INT(T$5+60)))=0,"Веха не участвует в расчете выплат за квартал",1/SUMPRODUCT(($E$16:$E$35<>"")*(IF(IF(P$16:P$35="",$G$16:$G$35,P$16:P$35)="",0,INT(IF(P$16:P$35="",$G$16:$G$35,P$16:P$35)))>=INT(T$5+60)))))))),"")} -> 0.16666667 | S20: =IFERROR(IF(AND(T$12<>"",$H20>T$12),0,IF($I20<-100,0,IF(IF(AND($F$1="Да",$F$2=T$5),TRUE(),IF(P20="",$G20,P20)>=T$5+60),IF($H20="","",IF(AND(T$1="МП",_xlfn.ISFORMULA(T20)),"Впиши средний KPI за прошлые кварталы",T$8*R20*IF(AND(OR(T$1="КУПК",T$1="РУПК"),$F$3="Да"),90%+10%*MAX(0,MIN(1,($G$3-40%)*2)),1)*MIN((1+IF(P20="",$I20,P20-$H20)*1%)*IF(T$1="РУПК",1,IF(T$1="МП",(T20-50%)*2,T$10)),IF(T$1="РУПК",1.5,IF(T$1="МП",(T20-50%)*2*1.5,1.5*T$10))))),"Веха не участвует в расчете выплат за квартал"))),"") | T20: =IFERROR(IF(ISTEXT(S20),"",IF(AND(OR(T$1="КУПК",T$1="КУПК (РП/ЗРП)"),S20>0),IF($H20="","",CONCATENATE("Расчёт при NPV = ",TEXT(T$11,"# ##0 ₽"),". Коэф. фин. рез. = ",ROUND(T$10,2))),"")),"")
B21: =CONCATENATE(E21," ",F21) -> Мотивационная веха 6 | C21: 4 | D21: =D20+1 -> 6 | E21: Мотивационная веха 6 | G21: 46234 | I21: =IF(H21="","",G21-H21) | J21: =IF(H21="","",(DATE(YEAR(H21),ROUNDUP(MONTH(H21)/3,0)*3+2,10)-IF(WEEKDAY(DATE(YEAR(H21),ROUNDUP(MONTH(H21)/3,0)*3+2,10),2)>5,WEEKDAY(DATE(YEAR(H21),ROUNDUP(MONTH(H21)/3,0)*3+2,10),2)-5,0))) | M21: {=IFERROR( IF($E21="","",IF(AND($F$1="Да",$F$2=O$5),IF(COUNTIF($E$16:$E$35,"<>")=0,"Веха не участвует в расчете выплат за квартал",1/COUNTIF($E$16:$E$35,"<>")),IF(IF(K21="",$G21,K21)="", "Веха не участвует в расчете выплат за квартал", IF(INT(IF(K21="",$G21,K21))<INT(O$5+60), "Веха не участвует в расчете выплат за квартал", IF(SUMPRODUCT(($E$16:$E$35<>"")*(IF(IF(K$16:K$35="",$G$16:$G$35,K$16:K$35)="",0,INT(IF(K$16:K$35="",$G$16:$G$35,K$16:K$35)))>=INT(O$5+60)))=0,"Веха не участвует в расчете выплат за квартал",1/SUMPRODUCT(($E$16:$E$35<>"")*(IF(IF(K$16:K$35="",$G$16:$G$35,K$16:K$35)="",0,INT(IF(K$16:K$35="",$G$16:$G$35,K$16:K$35)))>=INT(O$5+60)))))))),"")} -> 0.16666667 | N21: =IFERROR(IF(AND(O$12<>"",$H21>O$12),0,IF($I21<-100,0,IF(IF(AND($F$1="Да",$F$2=O$5),TRUE(),IF(K21="",$G21,K21)>=O$5+60),IF($H21="","",IF(AND(O$1="МП",_xlfn.ISFORMULA(O21)),"Впиши средний KPI за прошлые кварталы",O$8*M21*IF(AND(OR(O$1="КУПК",O$1="РУПК"),$F$3="Да"),90%+10%*MAX(0,MIN(1,($G$3-40%)*2)),1)*MIN((1+IF(K21="",$I21,K21-$H21)*1%)*IF(O$1="РУПК",1,IF(O$1="МП",(O21-50%)*2,O$10)),IF(O$1="РУПК",1.5,IF(O$1="МП",(O21-50%)*2*1.5,1.5*O$10))))),"Веха не участвует в расчете выплат за квартал"))),"") | O21: =IFERROR(IF(ISTEXT(N21),"",IF(AND(OR(O$1="КУПК",O$1="КУПК (РП/ЗРП)"),N21>0),IF($H21="","",CONCATENATE("Расчёт при NPV = ",TEXT(O$11,"# ##0 ₽"),". Коэф. фин. рез. = ",ROUND(O$10,2))),"")),"") | R21: {=IFERROR( IF($E21="","",IF(AND($F$1="Да",$F$2=T$5),IF(COUNTIF($E$16:$E$35,"<>")=0,"Веха не участвует в расчете выплат за квартал",1/COUNTIF($E$16:$E$35,"<>")),IF(IF(P21="",$G21,P21)="", "Веха не участвует в расчете выплат за квартал", IF(INT(IF(P21="",$G21,P21))<INT(T$5+60), "Веха не участвует в расчете выплат за квартал", IF(SUMPRODUCT(($E$16:$E$35<>"")*(IF(IF(P$16:P$35="",$G$16:$G$35,P$16:P$35)="",0,INT(IF(P$16:P$35="",$G$16:$G$35,P$16:P$35)))>=INT(T$5+60)))=0,"Веха не участвует в расчете выплат за квартал",1/SUMPRODUCT(($E$16:$E$35<>"")*(IF(IF(P$16:P$35="",$G$16:$G$35,P$16:P$35)="",0,INT(IF(P$16:P$35="",$G$16:$G$35,P$16:P$35)))>=INT(T$5+60)))))))),"")} -> 0.16666667 | S21: =IFERROR(IF(AND(T$12<>"",$H21>T$12),0,IF($I21<-100,0,IF(IF(AND($F$1="Да",$F$2=T$5),TRUE(),IF(P21="",$G21,P21)>=T$5+60),IF($H21="","",IF(AND(T$1="МП",_xlfn.ISFORMULA(T21)),"Впиши средний KPI за прошлые кварталы",T$8*R21*IF(AND(OR(T$1="КУПК",T$1="РУПК"),$F$3="Да"),90%+10%*MAX(0,MIN(1,($G$3-40%)*2)),1)*MIN((1+IF(P21="",$I21,P21-$H21)*1%)*IF(T$1="РУПК",1,IF(T$1="МП",(T21-50%)*2,T$10)),IF(T$1="РУПК",1.5,IF(T$1="МП",(T21-50%)*2*1.5,1.5*T$10))))),"Веха не участвует в расчете выплат за квартал"))),"") | T21: =IFERROR(IF(ISTEXT(S21),"",IF(AND(OR(T$1="КУПК",T$1="КУПК (РП/ЗРП)"),S21>0),IF($H21="","",CONCATENATE("Расчёт при NPV = ",TEXT(T$11,"# ##0 ₽"),". Коэф. фин. рез. = ",ROUND(T$10,2))),"")),"")
B22: =CONCATENATE(E22," ",F22) | C22: 4 | D22: =D21+1 -> 7 | I22: =IF(H22="","",G22-H22) | J22: =IF(H22="","",(DATE(YEAR(H22),ROUNDUP(MONTH(H22)/3,0)*3+2,10)-IF(WEEKDAY(DATE(YEAR(H22),ROUNDUP(MONTH(H22)/3,0)*3+2,10),2)>5,WEEKDAY(DATE(YEAR(H22),ROUNDUP(MONTH(H22)/3,0)*3+2,10),2)-5,0))) | M22: {=IFERROR( IF($E22="","",IF(AND($F$1="Да",$F$2=O$5),IF(COUNTIF($E$16:$E$35,"<>")=0,"Веха не участвует в расчете выплат за квартал",1/COUNTIF($E$16:$E$35,"<>")),IF(IF(K22="",$G22,K22)="", "Веха не участвует в расчете выплат за квартал", IF(INT(IF(K22="",$G22,K22))<INT(O$5+60), "Веха не участвует в расчете выплат за квартал", IF(SUMPRODUCT(($E$16:$E$35<>"")*(IF(IF(K$16:K$35="",$G$16:$G$35,K$16:K$35)="",0,INT(IF(K$16:K$35="",$G$16:$G$35,K$16:K$35)))>=INT(O$5+60)))=0,"Веха не участвует в расчете выплат за квартал",1/SUMPRODUCT(($E$16:$E$35<>"")*(IF(IF(K$16:K$35="",$G$16:$G$35,K$16:K$35)="",0,INT(IF(K$16:K$35="",$G$16:$G$35,K$16:K$35)))>=INT(O$5+60)))))))),"")} | N22: =IFERROR(IF(AND(O$12<>"",$H22>O$12),0,IF($I22<-100,0,IF(IF(AND($F$1="Да",$F$2=O$5),TRUE(),IF(K22="",$G22,K22)>=O$5+60),IF($H22="","",IF(AND(O$1="МП",_xlfn.ISFORMULA(O22)),"Впиши средний KPI за прошлые кварталы",O$8*M22*IF(AND(OR(O$1="КУПК",O$1="РУПК"),$F$3="Да"),90%+10%*MAX(0,MIN(1,($G$3-40%)*2)),1)*MIN((1+IF(K22="",$I22,K22-$H22)*1%)*IF(O$1="РУПК",1,IF(O$1="МП",(O22-50%)*2,O$10)),IF(O$1="РУПК",1.5,IF(O$1="МП",(O22-50%)*2*1.5,1.5*O$10))))),"Веха не участвует в расчете выплат за квартал"))),"") -> Веха не участвует в расчете выплат за квартал | O22: =IFERROR(IF(ISTEXT(N22),"",IF(AND(OR(O$1="КУПК",O$1="КУПК (РП/ЗРП)"),N22>0),IF($H22="","",CONCATENATE("Расчёт при NPV = ",TEXT(O$11,"# ##0 ₽"),". Коэф. фин. рез. = ",ROUND(O$10,2))),"")),"") | R22: {=IFERROR( IF($E22="","",IF(AND($F$1="Да",$F$2=T$5),IF(COUNTIF($E$16:$E$35,"<>")=0,"Веха не участвует в расчете выплат за квартал",1/COUNTIF($E$16:$E$35,"<>")),IF(IF(P22="",$G22,P22)="", "Веха не участвует в расчете выплат за квартал", IF(INT(IF(P22="",$G22,P22))<INT(T$5+60), "Веха не участвует в расчете выплат за квартал", IF(SUMPRODUCT(($E$16:$E$35<>"")*(IF(IF(P$16:P$35="",$G$16:$G$35,P$16:P$35)="",0,INT(IF(P$16:P$35="",$G$16:$G$35,P$16:P$35)))>=INT(T$5+60)))=0,"Веха не участвует в расчете выплат за квартал",1/SUMPRODUCT(($E$16:$E$35<>"")*(IF(IF(P$16:P$35="",$G$16:$G$35,P$16:P$35)="",0,INT(IF(P$16:P$35="",$G$16:$G$35,P$16:P$35)))>=INT(T$5+60)))))))),"")} | S22: =IFERROR(IF(AND(T$12<>"",$H22>T$12),0,IF($I22<-100,0,IF(IF(AND($F$1="Да",$F$2=T$5),TRUE(),IF(P22="",$G22,P22)>=T$5+60),IF($H22="","",IF(AND(T$1="МП",_xlfn.ISFORMULA(T22)),"Впиши средний KPI за прошлые кварталы",T$8*R22*IF(AND(OR(T$1="КУПК",T$1="РУПК"),$F$3="Да"),90%+10%*MAX(0,MIN(1,($G$3-40%)*2)),1)*MIN((1+IF(P22="",$I22,P22-$H22)*1%)*IF(T$1="РУПК",1,IF(T$1="МП",(T22-50%)*2,T$10)),IF(T$1="РУПК",1.5,IF(T$1="МП",(T22-50%)*2*1.5,1.5*T$10))))),"Веха не участвует в расчете выплат за квартал"))),"") -> Веха не участвует в расчете выплат за квартал | T22: =IFERROR(IF(ISTEXT(S22),"",IF(AND(OR(T$1="КУПК",T$1="КУПК (РП/ЗРП)"),S22>0),IF($H22="","",CONCATENATE("Расчёт при NPV = ",TEXT(T$11,"# ##0 ₽"),". Коэф. фин. рез. = ",ROUND(T$10,2))),"")),"")
B23: =CONCATENATE(E23," ",F23) | C23: 4 | D23: =D22+1 -> 8 | I23: =IF(H23="","",G23-H23) | J23: =IF(H23="","",(DATE(YEAR(H23),ROUNDUP(MONTH(H23)/3,0)*3+2,10)-IF(WEEKDAY(DATE(YEAR(H23),ROUNDUP(MONTH(H23)/3,0)*3+2,10),2)>5,WEEKDAY(DATE(YEAR(H23),ROUNDUP(MONTH(H23)/3,0)*3+2,10),2)-5,0))) | M23: {=IFERROR( IF($E23="","",IF(AND($F$1="Да",$F$2=O$5),IF(COUNTIF($E$16:$E$35,"<>")=0,"Веха не участвует в расчете выплат за квартал",1/COUNTIF($E$16:$E$35,"<>")),IF(IF(K23="",$G23,K23)="", "Веха не участвует в расчете выплат за квартал", IF(INT(IF(K23="",$G23,K23))<INT(O$5+60), "Веха не участвует в расчете выплат за квартал", IF(SUMPRODUCT(($E$16:$E$35<>"")*(IF(IF(K$16:K$35="",$G$16:$G$35,K$16:K$35)="",0,INT(IF(K$16:K$35="",$G$16:$G$35,K$16:K$35)))>=INT(O$5+60)))=0,"Веха не участвует в расчете выплат за квартал",1/SUMPRODUCT(($E$16:$E$35<>"")*(IF(IF(K$16:K$35="",$G$16:$G$35,K$16:K$35)="",0,INT(IF(K$16:K$35="",$G$16:$G$35,K$16:K$35)))>=INT(O$5+60)))))))),"")} | N23: =IFERROR(IF(AND(O$12<>"",$H23>O$12),0,IF($I23<-100,0,IF(IF(AND($F$1="Да",$F$2=O$5),TRUE(),IF(K23="",$G23,K23)>=O$5+60),IF($H23="","",IF(AND(O$1="МП",_xlfn.ISFORMULA(O23)),"Впиши средний KPI за прошлые кварталы",O$8*M23*IF(AND(OR(O$1="КУПК",O$1="РУПК"),$F$3="Да"),90%+10%*MAX(0,MIN(1,($G$3-40%)*2)),1)*MIN((1+IF(K23="",$I23,K23-$H23)*1%)*IF(O$1="РУПК",1,IF(O$1="МП",(O23-50%)*2,O$10)),IF(O$1="РУПК",1.5,IF(O$1="МП",(O23-50%)*2*1.5,1.5*O$10))))),"Веха не участвует в расчете выплат за квартал"))),"") -> Веха не участвует в расчете выплат за квартал | O23: =IFERROR(IF(ISTEXT(N23),"",IF(AND(OR(O$1="КУПК",O$1="КУПК (РП/ЗРП)"),N23>0),IF($H23="","",CONCATENATE("Расчёт при NPV = ",TEXT(O$11,"# ##0 ₽"),". Коэф. фин. рез. = ",ROUND(O$10,2))),"")),"") | R23: {=IFERROR( IF($E23="","",IF(AND($F$1="Да",$F$2=T$5),IF(COUNTIF($E$16:$E$35,"<>")=0,"Веха не участвует в расчете выплат за квартал",1/COUNTIF($E$16:$E$35,"<>")),IF(IF(P23="",$G23,P23)="", "Веха не участвует в расчете выплат за квартал", IF(INT(IF(P23="",$G23,P23))<INT(T$5+60), "Веха не участвует в расчете выплат за квартал", IF(SUMPRODUCT(($E$16:$E$35<>"")*(IF(IF(P$16:P$35="",$G$16:$G$35,P$16:P$35)="",0,INT(IF(P$16:P$35="",$G$16:$G$35,P$16:P$35)))>=INT(T$5+60)))=0,"Веха не участвует в расчете выплат за квартал",1/SUMPRODUCT(($E$16:$E$35<>"")*(IF(IF(P$16:P$35="",$G$16:$G$35,P$16:P$35)="",0,INT(IF(P$16:P$35="",$G$16:$G$35,P$16:P$35)))>=INT(T$5+60)))))))),"")} | S23: =IFERROR(IF(AND(T$12<>"",$H23>T$12),0,IF($I23<-100,0,IF(IF(AND($F$1="Да",$F$2=T$5),TRUE(),IF(P23="",$G23,P23)>=T$5+60),IF($H23="","",IF(AND(T$1="МП",_xlfn.ISFORMULA(T23)),"Впиши средний KPI за прошлые кварталы",T$8*R23*IF(AND(OR(T$1="КУПК",T$1="РУПК"),$F$3="Да"),90%+10%*MAX(0,MIN(1,($G$3-40%)*2)),1)*MIN((1+IF(P23="",$I23,P23-$H23)*1%)*IF(T$1="РУПК",1,IF(T$1="МП",(T23-50%)*2,T$10)),IF(T$1="РУПК",1.5,IF(T$1="МП",(T23-50%)*2*1.5,1.5*T$10))))),"Веха не участвует в расчете выплат за квартал"))),"") -> Веха не участвует в расчете выплат за квартал | T23: =IFERROR(IF(ISTEXT(S23),"",IF(AND(OR(T$1="КУПК",T$1="КУПК (РП/ЗРП)"),S23>0),IF($H23="","",CONCATENATE("Расчёт при NPV = ",TEXT(T$11,"# ##0 ₽"),". Коэф. фин. рез. = ",ROUND(T$10,2))),"")),"")
B24: =CONCATENATE(E24," ",F24) | C24: 4 | D24: =D23+1 -> 9 | I24: =IF(H24="","",G24-H24) | J24: =IF(H24="","",(DATE(YEAR(H24),ROUNDUP(MONTH(H24)/3,0)*3+2,10)-IF(WEEKDAY(DATE(YEAR(H24),ROUNDUP(MONTH(H24)/3,0)*3+2,10),2)>5,WEEKDAY(DATE(YEAR(H24),ROUNDUP(MONTH(H24)/3,0)*3+2,10),2)-5,0))) | M24: {=IFERROR( IF($E24="","",IF(AND($F$1="Да",$F$2=O$5),IF(COUNTIF($E$16:$E$35,"<>")=0,"Веха не участвует в расчете выплат за квартал",1/COUNTIF($E$16:$E$35,"<>")),IF(IF(K24="",$G24,K24)="", "Веха не участвует в расчете выплат за квартал", IF(INT(IF(K24="",$G24,K24))<INT(O$5+60), "Веха не участвует в расчете выплат за квартал", IF(SUMPRODUCT(($E$16:$E$35<>"")*(IF(IF(K$16:K$35="",$G$16:$G$35,K$16:K$35)="",0,INT(IF(K$16:K$35="",$G$16:$G$35,K$16:K$35)))>=INT(O$5+60)))=0,"Веха не участвует в расчете выплат за квартал",1/SUMPRODUCT(($E$16:$E$35<>"")*(IF(IF(K$16:K$35="",$G$16:$G$35,K$16:K$35)="",0,INT(IF(K$16:K$35="",$G$16:$G$35,K$16:K$35)))>=INT(O$5+60)))))))),"")} | N24: =IFERROR(IF(AND(O$12<>"",$H24>O$12),0,IF($I24<-100,0,IF(IF(AND($F$1="Да",$F$2=O$5),TRUE(),IF(K24="",$G24,K24)>=O$5+60),IF($H24="","",IF(AND(O$1="МП",_xlfn.ISFORMULA(O24)),"Впиши средний KPI за прошлые кварталы",O$8*M24*IF(AND(OR(O$1="КУПК",O$1="РУПК"),$F$3="Да"),90%+10%*MAX(0,MIN(1,($G$3-40%)*2)),1)*MIN((1+IF(K24="",$I24,K24-$H24)*1%)*IF(O$1="РУПК",1,IF(O$1="МП",(O24-50%)*2,O$10)),IF(O$1="РУПК",1.5,IF(O$1="МП",(O24-50%)*2*1.5,1.5*O$10))))),"Веха не участвует в расчете выплат за квартал"))),"") -> Веха не участвует в расчете выплат за квартал | O24: =IFERROR(IF(ISTEXT(N24),"",IF(AND(OR(O$1="КУПК",O$1="КУПК (РП/ЗРП)"),N24>0),IF($H24="","",CONCATENATE("Расчёт при NPV = ",TEXT(O$11,"# ##0 ₽"),". Коэф. фин. рез. = ",ROUND(O$10,2))),"")),"") | R24: {=IFERROR( IF($E24="","",IF(AND($F$1="Да",$F$2=T$5),IF(COUNTIF($E$16:$E$35,"<>")=0,"Веха не участвует в расчете выплат за квартал",1/COUNTIF($E$16:$E$35,"<>")),IF(IF(P24="",$G24,P24)="", "Веха не участвует в расчете выплат за квартал", IF(INT(IF(P24="",$G24,P24))<INT(T$5+60), "Веха не участвует в расчете выплат за квартал", IF(SUMPRODUCT(($E$16:$E$35<>"")*(IF(IF(P$16:P$35="",$G$16:$G$35,P$16:P$35)="",0,INT(IF(P$16:P$35="",$G$16:$G$35,P$16:P$35)))>=INT(T$5+60)))=0,"Веха не участвует в расчете выплат за квартал",1/SUMPRODUCT(($E$16:$E$35<>"")*(IF(IF(P$16:P$35="",$G$16:$G$35,P$16:P$35)="",0,INT(IF(P$16:P$35="",$G$16:$G$35,P$16:P$35)))>=INT(T$5+60)))))))),"")} | S24: =IFERROR(IF(AND(T$12<>"",$H24>T$12),0,IF($I24<-100,0,IF(IF(AND($F$1="Да",$F$2=T$5),TRUE(),IF(P24="",$G24,P24)>=T$5+60),IF($H24="","",IF(AND(T$1="МП",_xlfn.ISFORMULA(T24)),"Впиши средний KPI за прошлые кварталы",T$8*R24*IF(AND(OR(T$1="КУПК",T$1="РУПК"),$F$3="Да"),90%+10%*MAX(0,MIN(1,($G$3-40%)*2)),1)*MIN((1+IF(P24="",$I24,P24-$H24)*1%)*IF(T$1="РУПК",1,IF(T$1="МП",(T24-50%)*2,T$10)),IF(T$1="РУПК",1.5,IF(T$1="МП",(T24-50%)*2*1.5,1.5*T$10))))),"Веха не участвует в расчете выплат за квартал"))),"") -> Веха не участвует в расчете выплат за квартал | T24: =IFERROR(IF(ISTEXT(S24),"",IF(AND(OR(T$1="КУПК",T$1="КУПК (РП/ЗРП)"),S24>0),IF($H24="","",CONCATENATE("Расчёт при NPV = ",TEXT(T$11,"# ##0 ₽"),". Коэф. фин. рез. = ",ROUND(T$10,2))),"")),"")
B25: =CONCATENATE(E25," ",F25) | C25: 4 | D25: =D24+1 -> 10 | I25: =IF(H25="","",G25-H25) | J25: =IF(H25="","",(DATE(YEAR(H25),ROUNDUP(MONTH(H25)/3,0)*3+2,10)-IF(WEEKDAY(DATE(YEAR(H25),ROUNDUP(MONTH(H25)/3,0)*3+2,10),2)>5,WEEKDAY(DATE(YEAR(H25),ROUNDUP(MONTH(H25)/3,0)*3+2,10),2)-5,0))) | M25: {=IFERROR( IF($E25="","",IF(AND($F$1="Да",$F$2=O$5),IF(COUNTIF($E$16:$E$35,"<>")=0,"Веха не участвует в расчете выплат за квартал",1/COUNTIF($E$16:$E$35,"<>")),IF(IF(K25="",$G25,K25)="", "Веха не участвует в расчете выплат за квартал", IF(INT(IF(K25="",$G25,K25))<INT(O$5+60), "Веха не участвует в расчете выплат за квартал", IF(SUMPRODUCT(($E$16:$E$35<>"")*(IF(IF(K$16:K$35="",$G$16:$G$35,K$16:K$35)="",0,INT(IF(K$16:K$35="",$G$16:$G$35,K$16:K$35)))>=INT(O$5+60)))=0,"Веха не участвует в расчете выплат за квартал",1/SUMPRODUCT(($E$16:$E$35<>"")*(IF(IF(K$16:K$35="",$G$16:$G$35,K$16:K$35)="",0,INT(IF(K$16:K$35="",$G$16:$G$35,K$16:K$35)))>=INT(O$5+60)))))))),"")} | N25: =IFERROR(IF(AND(O$12<>"",$H25>O$12),0,IF($I25<-100,0,IF(IF(AND($F$1="Да",$F$2=O$5),TRUE(),IF(K25="",$G25,K25)>=O$5+60),IF($H25="","",IF(AND(O$1="МП",_xlfn.ISFORMULA(O25)),"Впиши средний KPI за прошлые кварталы",O$8*M25*IF(AND(OR(O$1="КУПК",O$1="РУПК"),$F$3="Да"),90%+10%*MAX(0,MIN(1,($G$3-40%)*2)),1)*MIN((1+IF(K25="",$I25,K25-$H25)*1%)*IF(O$1="РУПК",1,IF(O$1="МП",(O25-50%)*2,O$10)),IF(O$1="РУПК",1.5,IF(O$1="МП",(O25-50%)*2*1.5,1.5*O$10))))),"Веха не участвует в расчете выплат за квартал"))),"") -> Веха не участвует в расчете выплат за квартал | O25: =IFERROR(IF(ISTEXT(N25),"",IF(AND(OR(O$1="КУПК",O$1="КУПК (РП/ЗРП)"),N25>0),IF($H25="","",CONCATENATE("Расчёт при NPV = ",TEXT(O$11,"# ##0 ₽"),". Коэф. фин. рез. = ",ROUND(O$10,2))),"")),"") | R25: {=IFERROR( IF($E25="","",IF(AND($F$1="Да",$F$2=T$5),IF(COUNTIF($E$16:$E$35,"<>")=0,"Веха не участвует в расчете выплат за квартал",1/COUNTIF($E$16:$E$35,"<>")),IF(IF(P25="",$G25,P25)="", "Веха не участвует в расчете выплат за квартал", IF(INT(IF(P25="",$G25,P25))<INT(T$5+60), "Веха не участвует в расчете выплат за квартал", IF(SUMPRODUCT(($E$16:$E$35<>"")*(IF(IF(P$16:P$35="",$G$16:$G$35,P$16:P$35)="",0,INT(IF(P$16:P$35="",$G$16:$G$35,P$16:P$35)))>=INT(T$5+60)))=0,"Веха не участвует в расчете выплат за квартал",1/SUMPRODUCT(($E$16:$E$35<>"")*(IF(IF(P$16:P$35="",$G$16:$G$35,P$16:P$35)="",0,INT(IF(P$16:P$35="",$G$16:$G$35,P$16:P$35)))>=INT(T$5+60)))))))),"")} | S25: =IFERROR(IF(AND(T$12<>"",$H25>T$12),0,IF($I25<-100,0,IF(IF(AND($F$1="Да",$F$2=T$5),TRUE(),IF(P25="",$G25,P25)>=T$5+60),IF($H25="","",IF(AND(T$1="МП",_xlfn.ISFORMULA(T25)),"Впиши средний KPI за прошлые кварталы",T$8*R25*IF(AND(OR(T$1="КУПК",T$1="РУПК"),$F$3="Да"),90%+10%*MAX(0,MIN(1,($G$3-40%)*2)),1)*MIN((1+IF(P25="",$I25,P25-$H25)*1%)*IF(T$1="РУПК",1,IF(T$1="МП",(T25-50%)*2,T$10)),IF(T$1="РУПК",1.5,IF(T$1="МП",(T25-50%)*2*1.5,1.5*T$10))))),"Веха не участвует в расчете выплат за квартал"))),"") -> Веха не участвует в расчете выплат за квартал | T25: =IFERROR(IF(ISTEXT(S25),"",IF(AND(OR(T$1="КУПК",T$1="КУПК (РП/ЗРП)"),S25>0),IF($H25="","",CONCATENATE("Расчёт при NPV = ",TEXT(T$11,"# ##0 ₽"),". Коэф. фин. рез. = ",ROUND(T$10,2))),"")),"")
B26: =CONCATENATE(E26," ",F26) | C26: 4 | D26: =D25+1 -> 11 | I26: =IF(H26="","",G26-H26) | J26: =IF(H26="","",(DATE(YEAR(H26),ROUNDUP(MONTH(H26)/3,0)*3+2,10)-IF(WEEKDAY(DATE(YEAR(H26),ROUNDUP(MONTH(H26)/3,0)*3+2,10),2)>5,WEEKDAY(DATE(YEAR(H26),ROUNDUP(MONTH(H26)/3,0)*3+2,10),2)-5,0))) | M26: {=IFERROR( IF($E26="","",IF(AND($F$1="Да",$F$2=O$5),IF(COUNTIF($E$16:$E$35,"<>")=0,"Веха не участвует в расчете выплат за квартал",1/COUNTIF($E$16:$E$35,"<>")),IF(IF(K26="",$G26,K26)="", "Веха не участвует в расчете выплат за квартал", IF(INT(IF(K26="",$G26,K26))<INT(O$5+60), "Веха не участвует в расчете выплат за квартал", IF(SUMPRODUCT(($E$16:$E$35<>"")*(IF(IF(K$16:K$35="",$G$16:$G$35,K$16:K$35)="",0,INT(IF(K$16:K$35="",$G$16:$G$35,K$16:K$35)))>=INT(O$5+60)))=0,"Веха не участвует в расчете выплат за квартал",1/SUMPRODUCT(($E$16:$E$35<>"")*(IF(IF(K$16:K$35="",$G$16:$G$35,K$16:K$35)="",0,INT(IF(K$16:K$35="",$G$16:$G$35,K$16:K$35)))>=INT(O$5+60)))))))),"")} | N26: =IFERROR(IF(AND(O$12<>"",$H26>O$12),0,IF($I26<-100,0,IF(IF(AND($F$1="Да",$F$2=O$5),TRUE(),IF(K26="",$G26,K26)>=O$5+60),IF($H26="","",IF(AND(O$1="МП",_xlfn.ISFORMULA(O26)),"Впиши средний KPI за прошлые кварталы",O$8*M26*IF(AND(OR(O$1="КУПК",O$1="РУПК"),$F$3="Да"),90%+10%*MAX(0,MIN(1,($G$3-40%)*2)),1)*MIN((1+IF(K26="",$I26,K26-$H26)*1%)*IF(O$1="РУПК",1,IF(O$1="МП",(O26-50%)*2,O$10)),IF(O$1="РУПК",1.5,IF(O$1="МП",(O26-50%)*2*1.5,1.5*O$10))))),"Веха не участвует в расчете выплат за квартал"))),"") -> Веха не участвует в расчете выплат за квартал | O26: =IFERROR(IF(ISTEXT(N26),"",IF(AND(OR(O$1="КУПК",O$1="КУПК (РП/ЗРП)"),N26>0),IF($H26="","",CONCATENATE("Расчёт при NPV = ",TEXT(O$11,"# ##0 ₽"),". Коэф. фин. рез. = ",ROUND(O$10,2))),"")),"") | R26: {=IFERROR( IF($E26="","",IF(AND($F$1="Да",$F$2=T$5),IF(COUNTIF($E$16:$E$35,"<>")=0,"Веха не участвует в расчете выплат за квартал",1/COUNTIF($E$16:$E$35,"<>")),IF(IF(P26="",$G26,P26)="", "Веха не участвует в расчете выплат за квартал", IF(INT(IF(P26="",$G26,P26))<INT(T$5+60), "Веха не участвует в расчете выплат за квартал", IF(SUMPRODUCT(($E$16:$E$35<>"")*(IF(IF(P$16:P$35="",$G$16:$G$35,P$16:P$35)="",0,INT(IF(P$16:P$35="",$G$16:$G$35,P$16:P$35)))>=INT(T$5+60)))=0,"Веха не участвует в расчете выплат за квартал",1/SUMPRODUCT(($E$16:$E$35<>"")*(IF(IF(P$16:P$35="",$G$16:$G$35,P$16:P$35)="",0,INT(IF(P$16:P$35="",$G$16:$G$35,P$16:P$35)))>=INT(T$5+60)))))))),"")} | S26: =IFERROR(IF(AND(T$12<>"",$H26>T$12),0,IF($I26<-100,0,IF(IF(AND($F$1="Да",$F$2=T$5),TRUE(),IF(P26="",$G26,P26)>=T$5+60),IF($H26="","",IF(AND(T$1="МП",_xlfn.ISFORMULA(T26)),"Впиши средний KPI за прошлые кварталы",T$8*R26*IF(AND(OR(T$1="КУПК",T$1="РУПК"),$F$3="Да"),90%+10%*MAX(0,MIN(1,($G$3-40%)*2)),1)*MIN((1+IF(P26="",$I26,P26-$H26)*1%)*IF(T$1="РУПК",1,IF(T$1="МП",(T26-50%)*2,T$10)),IF(T$1="РУПК",1.5,IF(T$1="МП",(T26-50%)*2*1.5,1.5*T$10))))),"Веха не участвует в расчете выплат за квартал"))),"") -> Веха не участвует в расчете выплат за квартал | T26: =IFERROR(IF(ISTEXT(S26),"",IF(AND(OR(T$1="КУПК",T$1="КУПК (РП/ЗРП)"),S26>0),IF($H26="","",CONCATENATE("Расчёт при NPV = ",TEXT(T$11,"# ##0 ₽"),". Коэф. фин. рез. = ",ROUND(T$10,2))),"")),"")
B27: =CONCATENATE(E27," ",F27) | C27: 4 | D27: =D26+1 -> 12 | I27: =IF(H27="","",G27-H27) | J27: =IF(H27="","",(DATE(YEAR(H27),ROUNDUP(MONTH(H27)/3,0)*3+2,10)-IF(WEEKDAY(DATE(YEAR(H27),ROUNDUP(MONTH(H27)/3,0)*3+2,10),2)>5,WEEKDAY(DATE(YEAR(H27),ROUNDUP(MONTH(H27)/3,0)*3+2,10),2)-5,0))) | M27: {=IFERROR( IF($E27="","",IF(AND($F$1="Да",$F$2=O$5),IF(COUNTIF($E$16:$E$35,"<>")=0,"Веха не участвует в расчете выплат за квартал",1/COUNTIF($E$16:$E$35,"<>")),IF(IF(K27="",$G27,K27)="", "Веха не участвует в расчете выплат за квартал", IF(INT(IF(K27="",$G27,K27))<INT(O$5+60), "Веха не участвует в расчете выплат за квартал", IF(SUMPRODUCT(($E$16:$E$35<>"")*(IF(IF(K$16:K$35="",$G$16:$G$35,K$16:K$35)="",0,INT(IF(K$16:K$35="",$G$16:$G$35,K$16:K$35)))>=INT(O$5+60)))=0,"Веха не участвует в расчете выплат за квартал",1/SUMPRODUCT(($E$16:$E$35<>"")*(IF(IF(K$16:K$35="",$G$16:$G$35,K$16:K$35)="",0,INT(IF(K$16:K$35="",$G$16:$G$35,K$16:K$35)))>=INT(O$5+60)))))))),"")} | N27: =IFERROR(IF(AND(O$12<>"",$H27>O$12),0,IF($I27<-100,0,IF(IF(AND($F$1="Да",$F$2=O$5),TRUE(),IF(K27="",$G27,K27)>=O$5+60),IF($H27="","",IF(AND(O$1="МП",_xlfn.ISFORMULA(O27)),"Впиши средний KPI за прошлые кварталы",O$8*M27*IF(AND(OR(O$1="КУПК",O$1="РУПК"),$F$3="Да"),90%+10%*MAX(0,MIN(1,($G$3-40%)*2)),1)*MIN((1+IF(K27="",$I27,K27-$H27)*1%)*IF(O$1="РУПК",1,IF(O$1="МП",(O27-50%)*2,O$10)),IF(O$1="РУПК",1.5,IF(O$1="МП",(O27-50%)*2*1.5,1.5*O$10))))),"Веха не участвует в расчете выплат за квартал"))),"") -> Веха не участвует в расчете выплат за квартал | O27: =IFERROR(IF(ISTEXT(N27),"",IF(AND(OR(O$1="КУПК",O$1="КУПК (РП/ЗРП)"),N27>0),IF($H27="","",CONCATENATE("Расчёт при NPV = ",TEXT(O$11,"# ##0 ₽"),". Коэф. фин. рез. = ",ROUND(O$10,2))),"")),"") | R27: {=IFERROR( IF($E27="","",IF(AND($F$1="Да",$F$2=T$5),IF(COUNTIF($E$16:$E$35,"<>")=0,"Веха не участвует в расчете выплат за квартал",1/COUNTIF($E$16:$E$35,"<>")),IF(IF(P27="",$G27,P27)="", "Веха не участвует в расчете выплат за квартал", IF(INT(IF(P27="",$G27,P27))<INT(T$5+60), "Веха не участвует в расчете выплат за квартал", IF(SUMPRODUCT(($E$16:$E$35<>"")*(IF(IF(P$16:P$35="",$G$16:$G$35,P$16:P$35)="",0,INT(IF(P$16:P$35="",$G$16:$G$35,P$16:P$35)))>=INT(T$5+60)))=0,"Веха не участвует в расчете выплат за квартал",1/SUMPRODUCT(($E$16:$E$35<>"")*(IF(IF(P$16:P$35="",$G$16:$G$35,P$16:P$35)="",0,INT(IF(P$16:P$35="",$G$16:$G$35,P$16:P$35)))>=INT(T$5+60)))))))),"")} | S27: =IFERROR(IF(AND(T$12<>"",$H27>T$12),0,IF($I27<-100,0,IF(IF(AND($F$1="Да",$F$2=T$5),TRUE(),IF(P27="",$G27,P27)>=T$5+60),IF($H27="","",IF(AND(T$1="МП",_xlfn.ISFORMULA(T27)),"Впиши средний KPI за прошлые кварталы",T$8*R27*IF(AND(OR(T$1="КУПК",T$1="РУПК"),$F$3="Да"),90%+10%*MAX(0,MIN(1,($G$3-40%)*2)),1)*MIN((1+IF(P27="",$I27,P27-$H27)*1%)*IF(T$1="РУПК",1,IF(T$1="МП",(T27-50%)*2,T$10)),IF(T$1="РУПК",1.5,IF(T$1="МП",(T27-50%)*2*1.5,1.5*T$10))))),"Веха не участвует в расчете выплат за квартал"))),"") -> Веха не участвует в расчете выплат за квартал | T27: =IFERROR(IF(ISTEXT(S27),"",IF(AND(OR(T$1="КУПК",T$1="КУПК (РП/ЗРП)"),S27>0),IF($H27="","",CONCATENATE("Расчёт при NPV = ",TEXT(T$11,"# ##0 ₽"),". Коэф. фин. рез. = ",ROUND(T$10,2))),"")),"")
B28: =CONCATENATE(E28," ",F28) | C28: 4 | D28: =D27+1 -> 13 | I28: =IF(H28="","",G28-H28) | J28: =IF(H28="","",(DATE(YEAR(H28),ROUNDUP(MONTH(H28)/3,0)*3+2,10)-IF(WEEKDAY(DATE(YEAR(H28),ROUNDUP(MONTH(H28)/3,0)*3+2,10),2)>5,WEEKDAY(DATE(YEAR(H28),ROUNDUP(MONTH(H28)/3,0)*3+2,10),2)-5,0))) | M28: {=IFERROR( IF($E28="","",IF(AND($F$1="Да",$F$2=O$5),IF(COUNTIF($E$16:$E$35,"<>")=0,"Веха не участвует в расчете выплат за квартал",1/COUNTIF($E$16:$E$35,"<>")),IF(IF(K28="",$G28,K28)="", "Веха не участвует в расчете выплат за квартал", IF(INT(IF(K28="",$G28,K28))<INT(O$5+60), "Веха не участвует в расчете выплат за квартал", IF(SUMPRODUCT(($E$16:$E$35<>"")*(IF(IF(K$16:K$35="",$G$16:$G$35,K$16:K$35)="",0,INT(IF(K$16:K$35="",$G$16:$G$35,K$16:K$35)))>=INT(O$5+60)))=0,"Веха не участвует в расчете выплат за квартал",1/SUMPRODUCT(($E$16:$E$35<>"")*(IF(IF(K$16:K$35="",$G$16:$G$35,K$16:K$35)="",0,INT(IF(K$16:K$35="",$G$16:$G$35,K$16:K$35)))>=INT(O$5+60)))))))),"")} | N28: =IFERROR(IF(AND(O$12<>"",$H28>O$12),0,IF($I28<-100,0,IF(IF(AND($F$1="Да",$F$2=O$5),TRUE(),IF(K28="",$G28,K28)>=O$5+60),IF($H28="","",IF(AND(O$1="МП",_xlfn.ISFORMULA(O28)),"Впиши средний KPI за прошлые кварталы",O$8*M28*IF(AND(OR(O$1="КУПК",O$1="РУПК"),$F$3="Да"),90%+10%*MAX(0,MIN(1,($G$3-40%)*2)),1)*MIN((1+IF(K28="",$I28,K28-$H28)*1%)*IF(O$1="РУПК",1,IF(O$1="МП",(O28-50%)*2,O$10)),IF(O$1="РУПК",1.5,IF(O$1="МП",(O28-50%)*2*1.5,1.5*O$10))))),"Веха не участвует в расчете выплат за квартал"))),"") -> Веха не участвует в расчете выплат за квартал | O28: =IFERROR(IF(ISTEXT(N28),"",IF(AND(OR(O$1="КУПК",O$1="КУПК (РП/ЗРП)"),N28>0),IF($H28="","",CONCATENATE("Расчёт при NPV = ",TEXT(O$11,"# ##0 ₽"),". Коэф. фин. рез. = ",ROUND(O$10,2))),"")),"") | R28: {=IFERROR( IF($E28="","",IF(AND($F$1="Да",$F$2=T$5),IF(COUNTIF($E$16:$E$35,"<>")=0,"Веха не участвует в расчете выплат за квартал",1/COUNTIF($E$16:$E$35,"<>")),IF(IF(P28="",$G28,P28)="", "Веха не участвует в расчете выплат за квартал", IF(INT(IF(P28="",$G28,P28))<INT(T$5+60), "Веха не участвует в расчете выплат за квартал", IF(SUMPRODUCT(($E$16:$E$35<>"")*(IF(IF(P$16:P$35="",$G$16:$G$35,P$16:P$35)="",0,INT(IF(P$16:P$35="",$G$16:$G$35,P$16:P$35)))>=INT(T$5+60)))=0,"Веха не участвует в расчете выплат за квартал",1/SUMPRODUCT(($E$16:$E$35<>"")*(IF(IF(P$16:P$35="",$G$16:$G$35,P$16:P$35)="",0,INT(IF(P$16:P$35="",$G$16:$G$35,P$16:P$35)))>=INT(T$5+60)))))))),"")} | S28: =IFERROR(IF(AND(T$12<>"",$H28>T$12),0,IF($I28<-100,0,IF(IF(AND($F$1="Да",$F$2=T$5),TRUE(),IF(P28="",$G28,P28)>=T$5+60),IF($H28="","",IF(AND(T$1="МП",_xlfn.ISFORMULA(T28)),"Впиши средний KPI за прошлые кварталы",T$8*R28*IF(AND(OR(T$1="КУПК",T$1="РУПК"),$F$3="Да"),90%+10%*MAX(0,MIN(1,($G$3-40%)*2)),1)*MIN((1+IF(P28="",$I28,P28-$H28)*1%)*IF(T$1="РУПК",1,IF(T$1="МП",(T28-50%)*2,T$10)),IF(T$1="РУПК",1.5,IF(T$1="МП",(T28-50%)*2*1.5,1.5*T$10))))),"Веха не участвует в расчете выплат за квартал"))),"") -> Веха не участвует в расчете выплат за квартал | T28: =IFERROR(IF(ISTEXT(S28),"",IF(AND(OR(T$1="КУПК",T$1="КУПК (РП/ЗРП)"),S28>0),IF($H28="","",CONCATENATE("Расчёт при NPV = ",TEXT(T$11,"# ##0 ₽"),". Коэф. фин. рез. = ",ROUND(T$10,2))),"")),"")
B29: =CONCATENATE(E29," ",F29) | C29: 4 | D29: =D28+1 -> 14 | I29: =IF(H29="","",G29-H29) | J29: =IF(H29="","",(DATE(YEAR(H29),ROUNDUP(MONTH(H29)/3,0)*3+2,10)-IF(WEEKDAY(DATE(YEAR(H29),ROUNDUP(MONTH(H29)/3,0)*3+2,10),2)>5,WEEKDAY(DATE(YEAR(H29),ROUNDUP(MONTH(H29)/3,0)*3+2,10),2)-5,0))) | M29: {=IFERROR( IF($E29="","",IF(AND($F$1="Да",$F$2=O$5),IF(COUNTIF($E$16:$E$35,"<>")=0,"Веха не участвует в расчете выплат за квартал",1/COUNTIF($E$16:$E$35,"<>")),IF(IF(K29="",$G29,K29)="", "Веха не участвует в расчете выплат за квартал", IF(INT(IF(K29="",$G29,K29))<INT(O$5+60), "Веха не участвует в расчете выплат за квартал", IF(SUMPRODUCT(($E$16:$E$35<>"")*(IF(IF(K$16:K$35="",$G$16:$G$35,K$16:K$35)="",0,INT(IF(K$16:K$35="",$G$16:$G$35,K$16:K$35)))>=INT(O$5+60)))=0,"Веха не участвует в расчете выплат за квартал",1/SUMPRODUCT(($E$16:$E$35<>"")*(IF(IF(K$16:K$35="",$G$16:$G$35,K$16:K$35)="",0,INT(IF(K$16:K$35="",$G$16:$G$35,K$16:K$35)))>=INT(O$5+60)))))))),"")} | N29: =IFERROR(IF(AND(O$12<>"",$H29>O$12),0,IF($I29<-100,0,IF(IF(AND($F$1="Да",$F$2=O$5),TRUE(),IF(K29="",$G29,K29)>=O$5+60),IF($H29="","",IF(AND(O$1="МП",_xlfn.ISFORMULA(O29)),"Впиши средний KPI за прошлые кварталы",O$8*M29*IF(AND(OR(O$1="КУПК",O$1="РУПК"),$F$3="Да"),90%+10%*MAX(0,MIN(1,($G$3-40%)*2)),1)*MIN((1+IF(K29="",$I29,K29-$H29)*1%)*IF(O$1="РУПК",1,IF(O$1="МП",(O29-50%)*2,O$10)),IF(O$1="РУПК",1.5,IF(O$1="МП",(O29-50%)*2*1.5,1.5*O$10))))),"Веха не участвует в расчете выплат за квартал"))),"") -> Веха не участвует в расчете выплат за квартал | O29: =IFERROR(IF(ISTEXT(N29),"",IF(AND(OR(O$1="КУПК",O$1="КУПК (РП/ЗРП)"),N29>0),IF($H29="","",CONCATENATE("Расчёт при NPV = ",TEXT(O$11,"# ##0 ₽"),". Коэф. фин. рез. = ",ROUND(O$10,2))),"")),"") | R29: {=IFERROR( IF($E29="","",IF(AND($F$1="Да",$F$2=T$5),IF(COUNTIF($E$16:$E$35,"<>")=0,"Веха не участвует в расчете выплат за квартал",1/COUNTIF($E$16:$E$35,"<>")),IF(IF(P29="",$G29,P29)="", "Веха не участвует в расчете выплат за квартал", IF(INT(IF(P29="",$G29,P29))<INT(T$5+60), "Веха не участвует в расчете выплат за квартал", IF(SUMPRODUCT(($E$16:$E$35<>"")*(IF(IF(P$16:P$35="",$G$16:$G$35,P$16:P$35)="",0,INT(IF(P$16:P$35="",$G$16:$G$35,P$16:P$35)))>=INT(T$5+60)))=0,"Веха не участвует в расчете выплат за квартал",1/SUMPRODUCT(($E$16:$E$35<>"")*(IF(IF(P$16:P$35="",$G$16:$G$35,P$16:P$35)="",0,INT(IF(P$16:P$35="",$G$16:$G$35,P$16:P$35)))>=INT(T$5+60)))))))),"")} | S29: =IFERROR(IF(AND(T$12<>"",$H29>T$12),0,IF($I29<-100,0,IF(IF(AND($F$1="Да",$F$2=T$5),TRUE(),IF(P29="",$G29,P29)>=T$5+60),IF($H29="","",IF(AND(T$1="МП",_xlfn.ISFORMULA(T29)),"Впиши средний KPI за прошлые кварталы",T$8*R29*IF(AND(OR(T$1="КУПК",T$1="РУПК"),$F$3="Да"),90%+10%*MAX(0,MIN(1,($G$3-40%)*2)),1)*MIN((1+IF(P29="",$I29,P29-$H29)*1%)*IF(T$1="РУПК",1,IF(T$1="МП",(T29-50%)*2,T$10)),IF(T$1="РУПК",1.5,IF(T$1="МП",(T29-50%)*2*1.5,1.5*T$10))))),"Веха не участвует в расчете выплат за квартал"))),"") -> Веха не участвует в расчете выплат за квартал | T29: =IFERROR(IF(ISTEXT(S29),"",IF(AND(OR(T$1="КУПК",T$1="КУПК (РП/ЗРП)"),S29>0),IF($H29="","",CONCATENATE("Расчёт при NPV = ",TEXT(T$11,"# ##0 ₽"),". Коэф. фин. рез. = ",ROUND(T$10,2))),"")),"")
B30: =CONCATENATE(E30," ",F30) | C30: 4 | D30: =D29+1 -> 15 | I30: =IF(H30="","",G30-H30) | J30: =IF(H30="","",(DATE(YEAR(H30),ROUNDUP(MONTH(H30)/3,0)*3+2,10)-IF(WEEKDAY(DATE(YEAR(H30),ROUNDUP(MONTH(H30)/3,0)*3+2,10),2)>5,WEEKDAY(DATE(YEAR(H30),ROUNDUP(MONTH(H30)/3,0)*3+2,10),2)-5,0))) | M30: {=IFERROR( IF($E30="","",IF(AND($F$1="Да",$F$2=O$5),IF(COUNTIF($E$16:$E$35,"<>")=0,"Веха не участвует в расчете выплат за квартал",1/COUNTIF($E$16:$E$35,"<>")),IF(IF(K30="",$G30,K30)="", "Веха не участвует в расчете выплат за квартал", IF(INT(IF(K30="",$G30,K30))<INT(O$5+60), "Веха не участвует в расчете выплат за квартал", IF(SUMPRODUCT(($E$16:$E$35<>"")*(IF(IF(K$16:K$35="",$G$16:$G$35,K$16:K$35)="",0,INT(IF(K$16:K$35="",$G$16:$G$35,K$16:K$35)))>=INT(O$5+60)))=0,"Веха не участвует в расчете выплат за квартал",1/SUMPRODUCT(($E$16:$E$35<>"")*(IF(IF(K$16:K$35="",$G$16:$G$35,K$16:K$35)="",0,INT(IF(K$16:K$35="",$G$16:$G$35,K$16:K$35)))>=INT(O$5+60)))))))),"")} | N30: =IFERROR(IF(AND(O$12<>"",$H30>O$12),0,IF($I30<-100,0,IF(IF(AND($F$1="Да",$F$2=O$5),TRUE(),IF(K30="",$G30,K30)>=O$5+60),IF($H30="","",IF(AND(O$1="МП",_xlfn.ISFORMULA(O30)),"Впиши средний KPI за прошлые кварталы",O$8*M30*IF(AND(OR(O$1="КУПК",O$1="РУПК"),$F$3="Да"),90%+10%*MAX(0,MIN(1,($G$3-40%)*2)),1)*MIN((1+IF(K30="",$I30,K30-$H30)*1%)*IF(O$1="РУПК",1,IF(O$1="МП",(O30-50%)*2,O$10)),IF(O$1="РУПК",1.5,IF(O$1="МП",(O30-50%)*2*1.5,1.5*O$10))))),"Веха не участвует в расчете выплат за квартал"))),"") -> Веха не участвует в расчете выплат за квартал | O30: =IFERROR(IF(ISTEXT(N30),"",IF(AND(OR(O$1="КУПК",O$1="КУПК (РП/ЗРП)"),N30>0),IF($H30="","",CONCATENATE("Расчёт при NPV = ",TEXT(O$11,"# ##0 ₽"),". Коэф. фин. рез. = ",ROUND(O$10,2))),"")),"") | R30: {=IFERROR( IF($E30="","",IF(AND($F$1="Да",$F$2=T$5),IF(COUNTIF($E$16:$E$35,"<>")=0,"Веха не участвует в расчете выплат за квартал",1/COUNTIF($E$16:$E$35,"<>")),IF(IF(P30="",$G30,P30)="", "Веха не участвует в расчете выплат за квартал", IF(INT(IF(P30="",$G30,P30))<INT(T$5+60), "Веха не участвует в расчете выплат за квартал", IF(SUMPRODUCT(($E$16:$E$35<>"")*(IF(IF(P$16:P$35="",$G$16:$G$35,P$16:P$35)="",0,INT(IF(P$16:P$35="",$G$16:$G$35,P$16:P$35)))>=INT(T$5+60)))=0,"Веха не участвует в расчете выплат за квартал",1/SUMPRODUCT(($E$16:$E$35<>"")*(IF(IF(P$16:P$35="",$G$16:$G$35,P$16:P$35)="",0,INT(IF(P$16:P$35="",$G$16:$G$35,P$16:P$35)))>=INT(T$5+60)))))))),"")} | S30: =IFERROR(IF(AND(T$12<>"",$H30>T$12),0,IF($I30<-100,0,IF(IF(AND($F$1="Да",$F$2=T$5),TRUE(),IF(P30="",$G30,P30)>=T$5+60),IF($H30="","",IF(AND(T$1="МП",_xlfn.ISFORMULA(T30)),"Впиши средний KPI за прошлые кварталы",T$8*R30*IF(AND(OR(T$1="КУПК",T$1="РУПК"),$F$3="Да"),90%+10%*MAX(0,MIN(1,($G$3-40%)*2)),1)*MIN((1+IF(P30="",$I30,P30-$H30)*1%)*IF(T$1="РУПК",1,IF(T$1="МП",(T30-50%)*2,T$10)),IF(T$1="РУПК",1.5,IF(T$1="МП",(T30-50%)*2*1.5,1.5*T$10))))),"Веха не участвует в расчете выплат за квартал"))),"") -> Веха не участвует в расчете выплат за квартал | T30: =IFERROR(IF(ISTEXT(S30),"",IF(AND(OR(T$1="КУПК",T$1="КУПК (РП/ЗРП)"),S30>0),IF($H30="","",CONCATENATE("Расчёт при NPV = ",TEXT(T$11,"# ##0 ₽"),". Коэф. фин. рез. = ",ROUND(T$10,2))),"")),"")
B31: =CONCATENATE(E31," ",F31) | C31: 4 | D31: =D30+1 -> 16 | I31: =IF(H31="","",G31-H31) | J31: =IF(H31="","",(DATE(YEAR(H31),ROUNDUP(MONTH(H31)/3,0)*3+2,10)-IF(WEEKDAY(DATE(YEAR(H31),ROUNDUP(MONTH(H31)/3,0)*3+2,10),2)>5,WEEKDAY(DATE(YEAR(H31),ROUNDUP(MONTH(H31)/3,0)*3+2,10),2)-5,0))) | M31: {=IFERROR( IF($E31="","",IF(AND($F$1="Да",$F$2=O$5),IF(COUNTIF($E$16:$E$35,"<>")=0,"Веха не участвует в расчете выплат за квартал",1/COUNTIF($E$16:$E$35,"<>")),IF(IF(K31="",$G31,K31)="", "Веха не участвует в расчете выплат за квартал", IF(INT(IF(K31="",$G31,K31))<INT(O$5+60), "Веха не участвует в расчете выплат за квартал", IF(SUMPRODUCT(($E$16:$E$35<>"")*(IF(IF(K$16:K$35="",$G$16:$G$35,K$16:K$35)="",0,INT(IF(K$16:K$35="",$G$16:$G$35,K$16:K$35)))>=INT(O$5+60)))=0,"Веха не участвует в расчете выплат за квартал",1/SUMPRODUCT(($E$16:$E$35<>"")*(IF(IF(K$16:K$35="",$G$16:$G$35,K$16:K$35)="",0,INT(IF(K$16:K$35="",$G$16:$G$35,K$16:K$35)))>=INT(O$5+60)))))))),"")} | N31: =IFERROR(IF(AND(O$12<>"",$H31>O$12),0,IF($I31<-100,0,IF(IF(AND($F$1="Да",$F$2=O$5),TRUE(),IF(K31="",$G31,K31)>=O$5+60),IF($H31="","",IF(AND(O$1="МП",_xlfn.ISFORMULA(O31)),"Впиши средний KPI за прошлые кварталы",O$8*M31*IF(AND(OR(O$1="КУПК",O$1="РУПК"),$F$3="Да"),90%+10%*MAX(0,MIN(1,($G$3-40%)*2)),1)*MIN((1+IF(K31="",$I31,K31-$H31)*1%)*IF(O$1="РУПК",1,IF(O$1="МП",(O31-50%)*2,O$10)),IF(O$1="РУПК",1.5,IF(O$1="МП",(O31-50%)*2*1.5,1.5*O$10))))),"Веха не участвует в расчете выплат за квартал"))),"") -> Веха не участвует в расчете выплат за квартал | O31: =IFERROR(IF(ISTEXT(N31),"",IF(AND(OR(O$1="КУПК",O$1="КУПК (РП/ЗРП)"),N31>0),IF($H31="","",CONCATENATE("Расчёт при NPV = ",TEXT(O$11,"# ##0 ₽"),". Коэф. фин. рез. = ",ROUND(O$10,2))),"")),"") | R31: {=IFERROR( IF($E31="","",IF(AND($F$1="Да",$F$2=T$5),IF(COUNTIF($E$16:$E$35,"<>")=0,"Веха не участвует в расчете выплат за квартал",1/COUNTIF($E$16:$E$35,"<>")),IF(IF(P31="",$G31,P31)="", "Веха не участвует в расчете выплат за квартал", IF(INT(IF(P31="",$G31,P31))<INT(T$5+60), "Веха не участвует в расчете выплат за квартал", IF(SUMPRODUCT(($E$16:$E$35<>"")*(IF(IF(P$16:P$35="",$G$16:$G$35,P$16:P$35)="",0,INT(IF(P$16:P$35="",$G$16:$G$35,P$16:P$35)))>=INT(T$5+60)))=0,"Веха не участвует в расчете выплат за квартал",1/SUMPRODUCT(($E$16:$E$35<>"")*(IF(IF(P$16:P$35="",$G$16:$G$35,P$16:P$35)="",0,INT(IF(P$16:P$35="",$G$16:$G$35,P$16:P$35)))>=INT(T$5+60)))))))),"")} | S31: =IFERROR(IF(AND(T$12<>"",$H31>T$12),0,IF($I31<-100,0,IF(IF(AND($F$1="Да",$F$2=T$5),TRUE(),IF(P31="",$G31,P31)>=T$5+60),IF($H31="","",IF(AND(T$1="МП",_xlfn.ISFORMULA(T31)),"Впиши средний KPI за прошлые кварталы",T$8*R31*IF(AND(OR(T$1="КУПК",T$1="РУПК"),$F$3="Да"),90%+10%*MAX(0,MIN(1,($G$3-40%)*2)),1)*MIN((1+IF(P31="",$I31,P31-$H31)*1%)*IF(T$1="РУПК",1,IF(T$1="МП",(T31-50%)*2,T$10)),IF(T$1="РУПК",1.5,IF(T$1="МП",(T31-50%)*2*1.5,1.5*T$10))))),"Веха не участвует в расчете выплат за квартал"))),"") -> Веха не участвует в расчете выплат за квартал | T31: =IFERROR(IF(ISTEXT(S31),"",IF(AND(OR(T$1="КУПК",T$1="КУПК (РП/ЗРП)"),S31>0),IF($H31="","",CONCATENATE("Расчёт при NPV = ",TEXT(T$11,"# ##0 ₽"),". Коэф. фин. рез. = ",ROUND(T$10,2))),"")),"")
